<?xml version="1.0" ?>
<robot name="two_link_arm">
  <link name="world"/>
  
  <joint name="joint1" type="revolute">
    <parent link="world"/>
    <child link="link1"/>
    <origin xyz="0 0 0" rpy="0 0 0"/>
    <axis xyz="0 1 0"/>
    <limit lower="-3.14159" upper="3.14159" effort="100" velocity="10"/>
  </joint>
  
  <link name="link1">
    <inertial>
      <origin xyz="0 0 0.5" rpy="0 0 0"/>
      <mass value="1"/>
      <inertia ixx="0.083" ixy="0" ixz="0" iyy="0.083" iyz="0" izz="0.005"/>
    </inertial>
    <visual>
      <origin xyz="0 0 0.5" rpy="0 0 0"/>
      <geometry>
        <cylinder radius="0.05" length="1.0"/>
      </geometry>
      <material name="blue">
        <color rgba="0 0 0.8 1"/>
      </material>
    </visual>
  </link>
  
  <joint name="joint2" type="revolute">
    <parent link="link1"/>
    <child link="link2"/>
    <origin xyz="0 0 1.0" rpy="0 0 0"/>
    <axis xyz="0 1 0"/>
    <limit lower="-3.14159" upper="3.14159" effort="100" velocity="10"/>
  </joint>
  
  <link name="link2">
    <inertial>
      <origin xyz="0 0 0.5" rpy="0 0 0"/>
      <mass value="1"/>
      <inertia ixx="0.083" ixy="0" ixz="0" iyy="0.083" iyz="0" izz="0.005"/>
    </inertial>
    <visual>
      <origin xyz="0 0 0.5" rpy="0 0 0"/>
      <geometry>
        <cylinder radius="0.05" length="1.0"/>
      </geometry>
      <material name="red">
        <color rgba="0.8 0 0 1"/>
      </material>
    </visual>
  </link>
  
  <link name="end_effector"/>
  <joint name="ee_fixed_joint" type="fixed">
      <parent link="link2"/>
      <child link="end_effector"/>
      <origin xyz="0 0 1.0" rpy="0 0 0"/>
  </joint>
</robot>
