<?xml version="1.0"?>
<robot name="golfer">
  <!-- Generated from canonical YAML specification -->
  <link name="pelvis">
    <inertial>
      <mass value="11.7"/>
      <inertia
        ixx="0.1337"
        ixy="0.0"
        ixz="0.0"
        iyy="0.1337"
        iyz="0.0"
        izz="0.1337"/>
    </inertial>
    <visual>
      <origin xyz="0.0 0.0 0.0" rpy="0.0 0.0 0.0"/>
      <geometry>
        <cylinder radius="0.15" length="0.4"/>
      </geometry>
      <material name="mat_pelvis">
        <color rgba="0.8 0.6 0.4 1.0"/>
      </material>
    </visual>
  </link>
  <joint name="pelvis_to_left_thigh_gimbal_z" type="revolute">
    <parent link="pelvis"/>
    <child link="left_thigh_gimbal_z"/>
    <origin xyz="0.0 0.09 -0.05" rpy="0.0 0.0 0.0"/>
    <axis xyz="0 1 0"/>
    <limit lower="-1.57" upper="1.57" effort="1000.0" velocity="10.0"/>
    <dynamics damping="2.5"/>
  </joint>
  <link name="left_thigh_gimbal_z">
    <inertial>
      <mass value="0.001"/>
      <inertia ixx="0.0001" ixy="0" ixz="0" iyy="0.0001" iyz="0" izz="0.0001"/>
    </inertial>
  </link>
  <joint name="left_thigh_gimbal_z_to_left_thigh_gimbal_y" type="revolute">
    <parent link="left_thigh_gimbal_z"/>
    <child link="left_thigh_gimbal_y"/>
    <origin xyz="0.0 0.0 0.0" rpy="0.0 0.0 0.0"/>
    <axis xyz="1 0 0"/>
    <limit lower="-0.87" upper="0.52" effort="1000.0" velocity="10.0"/>
    <dynamics damping="2.5"/>
  </joint>
  <link name="left_thigh_gimbal_y">
    <inertial>
      <mass value="0.001"/>
      <inertia ixx="0.0001" ixy="0" ixz="0" iyy="0.0001" iyz="0" izz="0.0001"/>
    </inertial>
  </link>
  <joint name="left_thigh_gimbal_y_to_left_thigh" type="revolute">
    <parent link="left_thigh_gimbal_y"/>
    <child link="left_thigh"/>
    <origin xyz="0.0 0.0 0.0" rpy="0.0 0.0 0.0"/>
    <axis xyz="0 0 1"/>
    <limit lower="-0.7" upper="0.7" effort="1000.0" velocity="10.0"/>
    <dynamics damping="2.5"/>
  </joint>
  <link name="left_thigh">
    <inertial>
      <mass value="7.05"/>
      <inertia
        ixx="0.1058"
        ixy="0.0"
        ixz="0.0"
        iyy="0.1058"
        iyz="0.0"
        izz="0.0203"/>
    </inertial>
    <visual>
      <origin xyz="0.0 0.0 0.0" rpy="0.0 0.0 0.0"/>
      <geometry>
        <cylinder radius="0.06" length="0.43"/>
      </geometry>
      <material name="mat_left_thigh">
        <color rgba="0.42 0.32 0.18 1.0"/>
      </material>
    </visual>
  </link>
  <joint name="left_thigh_to_left_shank" type="revolute">
    <parent link="left_thigh"/>
    <child link="left_shank"/>
    <origin xyz="0.0 0.0 -0.43" rpy="0.0 0.0 0.0"/>
    <axis xyz="0 1 0"/>
    <limit lower="0.0" upper="2.62" effort="1000.0" velocity="10.0"/>
    <dynamics damping="5.0"/>
  </joint>
  <link name="left_shank">
    <inertial>
      <mass value="3.53"/>
      <inertia
        ixx="0.0401"
        ixy="0.0"
        ixz="0.0"
        iyy="0.0042"
        iyz="0.0"
        izz="0.0042"/>
    </inertial>
    <visual>
      <origin xyz="0.0 0.0 0.0" rpy="0.0 0.0 0.0"/>
      <geometry>
        <cylinder radius="0.05" length="0.43"/>
      </geometry>
      <material name="mat_left_shank">
        <color rgba="0.38 0.28 0.16 1.0"/>
      </material>
    </visual>
  </link>
  <joint name="left_shank_to_left_foot_intermediate" type="revolute">
    <parent link="left_shank"/>
    <child link="left_foot_intermediate"/>
    <origin xyz="0.0 0.0 -0.43" rpy="0.0 0.0 0.0"/>
    <axis xyz="1 0 0"/>
    <limit lower="-0.7" upper="0.52" effort="1000.0" velocity="10.0"/>
    <dynamics damping="2.0"/>
  </joint>
  <link name="left_foot_intermediate">
    <inertial>
      <mass value="0.001"/>
      <inertia ixx="0.0001" ixy="0" ixz="0" iyy="0.0001" iyz="0" izz="0.0001"/>
    </inertial>
  </link>
  <joint name="left_foot_intermediate_to_left_foot" type="revolute">
    <parent link="left_foot_intermediate"/>
    <child link="left_foot"/>
    <origin xyz="0.0 0.0 0.0" rpy="0.0 0.0 0.0"/>
    <axis xyz="0 1 0"/>
    <limit lower="-0.35" upper="0.35" effort="1000.0" velocity="10.0"/>
    <dynamics damping="2.0"/>
  </joint>
  <link name="left_foot">
    <inertial>
      <mass value="1.37"/>
      <inertia
        ixx="0.0034"
        ixy="0.0"
        ixz="0.0"
        iyy="0.009"
        iyz="0.0"
        izz="0.009"/>
    </inertial>
    <visual>
      <origin xyz="0.0 0.0 0.0" rpy="0.0 0.0 0.0"/>
      <geometry>
        <box size="0.26 0.1 0.07"/>
      </geometry>
      <material name="mat_left_foot">
        <color rgba="0.34 0.24 0.14 1.0"/>
      </material>
    </visual>
  </link>
  <joint name="left_foot_to_left_toes" type="revolute">
    <parent link="left_foot"/>
    <child link="left_toes"/>
    <origin xyz="0.12 0.0 -0.02" rpy="0.0 0.0 0.0"/>
    <axis xyz="0 1 0"/>
    <limit lower="-0.35" upper="0.52" effort="1000.0" velocity="10.0"/>
    <dynamics damping="0.5"/>
  </joint>
  <link name="left_toes">
    <inertial>
      <mass value="0.3"/>
      <inertia
        ixx="0.0005"
        ixy="0.0"
        ixz="0.0"
        iyy="0.0005"
        iyz="0.0"
        izz="0.0002"/>
    </inertial>
    <visual>
      <origin xyz="0.0 0.0 0.0" rpy="0.0 0.0 0.0"/>
      <geometry>
        <box size="0.1 0.08 0.03"/>
      </geometry>
      <material name="mat_left_toes">
        <color rgba="0.32 0.22 0.12 1.0"/>
      </material>
    </visual>
  </link>
  <joint name="pelvis_to_lumbar1_intermediate" type="revolute">
    <parent link="pelvis"/>
    <child link="lumbar1_intermediate"/>
    <origin xyz="0.0 0.0 0.12" rpy="0.0 0.0 0.0"/>
    <axis xyz="1 0 0"/>
    <limit lower="-0.7" upper="0.52" effort="1000.0" velocity="10.0"/>
    <dynamics damping="2.0"/>
  </joint>
  <link name="lumbar1_intermediate">
    <inertial>
      <mass value="0.001"/>
      <inertia ixx="0.0001" ixy="0" ixz="0" iyy="0.0001" iyz="0" izz="0.0001"/>
    </inertial>
  </link>
  <joint name="lumbar1_intermediate_to_lumbar1" type="revolute">
    <parent link="lumbar1_intermediate"/>
    <child link="lumbar1"/>
    <origin xyz="0.0 0.0 0.0" rpy="0.0 0.0 0.0"/>
    <axis xyz="0 1 0"/>
    <limit lower="-0.35" upper="0.35" effort="1000.0" velocity="10.0"/>
    <dynamics damping="2.0"/>
  </joint>
  <link name="lumbar1">
    <inertial>
      <mass value="2.0"/>
      <inertia
        ixx="0.015"
        ixy="0.0"
        ixz="0.0"
        iyy="0.015"
        iyz="0.0"
        izz="0.002"/>
    </inertial>
    <visual>
      <origin xyz="0.0 0.0 0.0" rpy="0.0 0.0 0.0"/>
      <geometry>
        <cylinder radius="0.08" length="0.24"/>
      </geometry>
      <material name="mat_lumbar1">
        <color rgba="0.75 0.55 0.35 1.0"/>
      </material>
    </visual>
  </link>
  <joint name="lumbar1_to_lumbar2_intermediate" type="revolute">
    <parent link="lumbar1"/>
    <child link="lumbar2_intermediate"/>
    <origin xyz="0.0 0.0 0.12" rpy="0.0 0.0 0.0"/>
    <axis xyz="1 0 0"/>
    <limit lower="-0.7" upper="0.52" effort="1000.0" velocity="10.0"/>
    <dynamics damping="2.0"/>
  </joint>
  <link name="lumbar2_intermediate">
    <inertial>
      <mass value="0.001"/>
      <inertia ixx="0.0001" ixy="0" ixz="0" iyy="0.0001" iyz="0" izz="0.0001"/>
    </inertial>
  </link>
  <joint name="lumbar2_intermediate_to_lumbar2" type="revolute">
    <parent link="lumbar2_intermediate"/>
    <child link="lumbar2"/>
    <origin xyz="0.0 0.0 0.0" rpy="0.0 0.0 0.0"/>
    <axis xyz="0 1 0"/>
    <limit lower="-0.35" upper="0.35" effort="1000.0" velocity="10.0"/>
    <dynamics damping="2.0"/>
  </joint>
  <link name="lumbar2">
    <inertial>
      <mass value="2.0"/>
      <inertia
        ixx="0.015"
        ixy="0.0"
        ixz="0.0"
        iyy="0.015"
        iyz="0.0"
        izz="0.002"/>
    </inertial>
    <visual>
      <origin xyz="0.0 0.0 0.0" rpy="0.0 0.0 0.0"/>
      <geometry>
        <cylinder radius="0.08" length="0.24"/>
      </geometry>
      <material name="mat_lumbar2">
        <color rgba="0.74 0.54 0.34 1.0"/>
      </material>
    </visual>
  </link>
  <joint name="lumbar2_to_lumbar3_intermediate" type="revolute">
    <parent link="lumbar2"/>
    <child link="lumbar3_intermediate"/>
    <origin xyz="0.0 0.0 0.12" rpy="0.0 0.0 0.0"/>
    <axis xyz="1 0 0"/>
    <limit lower="-0.7" upper="0.52" effort="1000.0" velocity="10.0"/>
    <dynamics damping="2.0"/>
  </joint>
  <link name="lumbar3_intermediate">
    <inertial>
      <mass value="0.001"/>
      <inertia ixx="0.0001" ixy="0" ixz="0" iyy="0.0001" iyz="0" izz="0.0001"/>
    </inertial>
  </link>
  <joint name="lumbar3_intermediate_to_lumbar3" type="revolute">
    <parent link="lumbar3_intermediate"/>
    <child link="lumbar3"/>
    <origin xyz="0.0 0.0 0.0" rpy="0.0 0.0 0.0"/>
    <axis xyz="0 1 0"/>
    <limit lower="-0.35" upper="0.35" effort="1000.0" velocity="10.0"/>
    <dynamics damping="2.0"/>
  </joint>
  <link name="lumbar3">
    <inertial>
      <mass value="2.0"/>
      <inertia
        ixx="0.015"
        ixy="0.0"
        ixz="0.0"
        iyy="0.015"
        iyz="0.0"
        izz="0.002"/>
    </inertial>
    <visual>
      <origin xyz="0.0 0.0 0.0" rpy="0.0 0.0 0.0"/>
      <geometry>
        <cylinder radius="0.08" length="0.24"/>
      </geometry>
      <material name="mat_lumbar3">
        <color rgba="0.73 0.53 0.33 1.0"/>
      </material>
    </visual>
  </link>
  <joint name="lumbar3_to_thorax1" type="revolute">
    <parent link="lumbar3"/>
    <child link="thorax1"/>
    <origin xyz="0.0 0.0 0.12" rpy="0.0 0.0 0.0"/>
    <axis xyz="0 0 1"/>
    <limit lower="-1.0" upper="1.0" effort="1000.0" velocity="10.0"/>
    <dynamics damping="1.5"/>
  </joint>
  <link name="thorax1">
    <inertial>
      <mass value="1.5"/>
      <inertia
        ixx="0.012"
        ixy="0.0"
        ixz="0.0"
        iyy="0.012"
        iyz="0.0"
        izz="0.0015"/>
    </inertial>
    <visual>
      <origin xyz="0.0 0.0 0.0" rpy="0.0 0.0 0.0"/>
      <geometry>
        <cylinder radius="0.08" length="0.2"/>
      </geometry>
      <material name="mat_thorax1">
        <color rgba="0.7 0.5 0.3 1.0"/>
      </material>
    </visual>
  </link>
  <joint name="thorax1_to_thorax2" type="revolute">
    <parent link="thorax1"/>
    <child link="thorax2"/>
    <origin xyz="0.0 0.0 0.1" rpy="0.0 0.0 0.0"/>
    <axis xyz="0 0 1"/>
    <limit lower="-1.0" upper="1.0" effort="1000.0" velocity="10.0"/>
    <dynamics damping="1.5"/>
  </joint>
  <link name="thorax2">
    <inertial>
      <mass value="1.5"/>
      <inertia
        ixx="0.012"
        ixy="0.0"
        ixz="0.0"
        iyy="0.012"
        iyz="0.0"
        izz="0.0015"/>
    </inertial>
    <visual>
      <origin xyz="0.0 0.0 0.0" rpy="0.0 0.0 0.0"/>
      <geometry>
        <cylinder radius="0.08" length="0.2"/>
      </geometry>
      <material name="mat_thorax2">
        <color rgba="0.68 0.48 0.28 1.0"/>
      </material>
    </visual>
  </link>
  <joint name="thorax2_to_thorax3" type="revolute">
    <parent link="thorax2"/>
    <child link="thorax3"/>
    <origin xyz="0.0 0.0 0.1" rpy="0.0 0.0 0.0"/>
    <axis xyz="0 0 1"/>
    <limit lower="-1.0" upper="1.0" effort="1000.0" velocity="10.0"/>
    <dynamics damping="1.5"/>
  </joint>
  <link name="thorax3">
    <inertial>
      <mass value="1.5"/>
      <inertia
        ixx="0.012"
        ixy="0.0"
        ixz="0.0"
        iyy="0.012"
        iyz="0.0"
        izz="0.0015"/>
    </inertial>
    <visual>
      <origin xyz="0.0 0.0 0.0" rpy="0.0 0.0 0.0"/>
      <geometry>
        <cylinder radius="0.08" length="0.2"/>
      </geometry>
      <material name="mat_thorax3">
        <color rgba="0.66 0.46 0.26 1.0"/>
      </material>
    </visual>
  </link>
  <joint name="thorax3_to_scapula_left_intermediate" type="revolute">
    <parent link="thorax3"/>
    <child link="scapula_left_intermediate"/>
    <origin xyz="0.0 0.18 0.28" rpy="0.0 0.0 0.0"/>
    <axis xyz="0 0 1"/>
    <limit lower="-0.35" upper="0.7" effort="1000.0" velocity="10.0"/>
    <dynamics damping="1.0"/>
  </joint>
  <link name="scapula_left_intermediate">
    <inertial>
      <mass value="0.001"/>
      <inertia ixx="0.0001" ixy="0" ixz="0" iyy="0.0001" iyz="0" izz="0.0001"/>
    </inertial>
  </link>
  <joint name="scapula_left_intermediate_to_scapula_left" type="revolute">
    <parent link="scapula_left_intermediate"/>
    <child link="scapula_left"/>
    <origin xyz="0.0 0.0 0.0" rpy="0.0 0.0 0.0"/>
    <axis xyz="0 1 0"/>
    <limit lower="-0.52" upper="0.52" effort="1000.0" velocity="10.0"/>
    <dynamics damping="1.0"/>
  </joint>
  <link name="scapula_left">
    <inertial>
      <mass value="1.5"/>
      <inertia
        ixx="0.008"
        ixy="0.0"
        ixz="0.0"
        iyy="0.008"
        iyz="0.0"
        izz="0.003"/>
    </inertial>
    <visual>
      <origin xyz="0.0 0.0 0.0" rpy="0.0 0.0 0.0"/>
      <geometry>
        <box size="0.12 0.08 0.05"/>
      </geometry>
      <material name="mat_scapula_left">
        <color rgba="0.62 0.42 0.22 1.0"/>
      </material>
    </visual>
  </link>
  <joint name="scapula_left_to_upper_arm_left_gimbal_z" type="revolute">
    <parent link="scapula_left"/>
    <child link="upper_arm_left_gimbal_z"/>
    <origin xyz="0.0 0.04 0.1" rpy="0.0 0.0 0.0"/>
    <axis xyz="0 1 0"/>
    <limit lower="-1.57" upper="3.1416" effort="1000.0" velocity="10.0"/>
    <dynamics damping="1.5"/>
  </joint>
  <link name="upper_arm_left_gimbal_z">
    <inertial>
      <mass value="0.001"/>
      <inertia ixx="0.0001" ixy="0" ixz="0" iyy="0.0001" iyz="0" izz="0.0001"/>
    </inertial>
  </link>
  <joint name="upper_arm_left_gimbal_z_to_upper_arm_left_gimbal_y" type="revolute">
    <parent link="upper_arm_left_gimbal_z"/>
    <child link="upper_arm_left_gimbal_y"/>
    <origin xyz="0.0 0.0 0.0" rpy="0.0 0.0 0.0"/>
    <axis xyz="1 0 0"/>
    <limit lower="-0.52" upper="2.09" effort="1000.0" velocity="10.0"/>
    <dynamics damping="1.5"/>
  </joint>
  <link name="upper_arm_left_gimbal_y">
    <inertial>
      <mass value="0.001"/>
      <inertia ixx="0.0001" ixy="0" ixz="0" iyy="0.0001" iyz="0" izz="0.0001"/>
    </inertial>
  </link>
  <joint name="upper_arm_left_gimbal_y_to_upper_arm_left" type="revolute">
    <parent link="upper_arm_left_gimbal_y"/>
    <child link="upper_arm_left"/>
    <origin xyz="0.0 0.0 0.0" rpy="0.0 0.0 0.0"/>
    <axis xyz="0 0 1"/>
    <limit lower="-1.57" upper="1.57" effort="1000.0" velocity="10.0"/>
    <dynamics damping="1.5"/>
  </joint>
  <link name="upper_arm_left">
    <inertial>
      <mass value="1.98"/>
      <inertia
        ixx="0.0138"
        ixy="0.0"
        ixz="0.0"
        iyy="0.0138"
        iyz="0.0"
        izz="0.0021"/>
    </inertial>
    <visual>
      <origin xyz="0.0 0.0 0.0" rpy="0.0 0.0 0.0"/>
      <geometry>
        <cylinder radius="0.05" length="0.28"/>
      </geometry>
      <material name="mat_upper_arm_left">
        <color rgba="0.58 0.38 0.18 1.0"/>
      </material>
    </visual>
  </link>
  <joint name="upper_arm_left_to_forearm_left_intermediate" type="revolute">
    <parent link="upper_arm_left"/>
    <child link="forearm_left_intermediate"/>
    <origin xyz="0.0 0.0 -0.26" rpy="0.0 0.0 0.0"/>
    <axis xyz="0 1 0"/>
    <limit lower="0.0" upper="2.62" effort="1000.0" velocity="10.0"/>
    <dynamics damping="3.0"/>
  </joint>
  <link name="forearm_left_intermediate">
    <inertial>
      <mass value="0.001"/>
      <inertia ixx="0.0001" ixy="0" ixz="0" iyy="0.0001" iyz="0" izz="0.0001"/>
    </inertial>
  </link>
  <joint name="forearm_left_intermediate_to_forearm_left" type="revolute">
    <parent link="forearm_left_intermediate"/>
    <child link="forearm_left"/>
    <origin xyz="0.0 0.0 0.0" rpy="0.0 0.0 0.0"/>
    <axis xyz="1 0 0"/>
    <limit lower="-1.57" upper="1.57" effort="1000.0" velocity="10.0"/>
    <dynamics damping="3.0"/>
  </joint>
  <link name="forearm_left">
    <inertial>
      <mass value="1.18"/>
      <inertia
        ixx="0.0074"
        ixy="0.0"
        ixz="0.0"
        iyy="0.0074"
        iyz="0.0"
        izz="0.0009"/>
    </inertial>
    <visual>
      <origin xyz="0.0 0.0 0.0" rpy="0.0 0.0 0.0"/>
      <geometry>
        <cylinder radius="0.045" length="0.26"/>
      </geometry>
      <material name="mat_forearm_left">
        <color rgba="0.54 0.34 0.14 1.0"/>
      </material>
    </visual>
  </link>
  <joint name="forearm_left_to_hand_left_intermediate" type="revolute">
    <parent link="forearm_left"/>
    <child link="hand_left_intermediate"/>
    <origin xyz="0.0 0.0 -0.19" rpy="0.0 0.0 0.0"/>
    <axis xyz="0 1 0"/>
    <limit lower="-1.22" upper="1.22" effort="1000.0" velocity="10.0"/>
    <dynamics damping="1.5"/>
  </joint>
  <link name="hand_left_intermediate">
    <inertial>
      <mass value="0.001"/>
      <inertia ixx="0.0001" ixy="0" ixz="0" iyy="0.0001" iyz="0" izz="0.0001"/>
    </inertial>
  </link>
  <joint name="hand_left_intermediate_to_hand_left" type="revolute">
    <parent link="hand_left_intermediate"/>
    <child link="hand_left"/>
    <origin xyz="0.0 0.0 0.0" rpy="0.0 0.0 0.0"/>
    <axis xyz="0 0 1"/>
    <limit lower="-0.52" upper="0.7" effort="1000.0" velocity="10.0"/>
    <dynamics damping="1.5"/>
  </joint>
  <link name="hand_left">
    <inertial>
      <mass value="0.61"/>
      <inertia
        ixx="0.0011"
        ixy="0.0"
        ixz="0.0"
        iyy="0.0011"
        iyz="0.0"
        izz="0.0004"/>
    </inertial>
    <visual>
      <origin xyz="0.0 0.0 0.0" rpy="0.0 0.0 0.0"/>
      <geometry>
        <cylinder radius="0.04" length="0.19"/>
      </geometry>
      <material name="mat_hand_left">
        <color rgba="0.5 0.3 0.12 1.0"/>
      </material>
    </visual>
  </link>
  <joint name="hand_left_to_club_shaft" type="fixed">
    <parent link="hand_left"/>
    <child link="club_shaft"/>
    <origin xyz="0.0 0.0 -0.12" rpy="0.0 0.0 0.0"/>
  </joint>
  <link name="club_shaft">
    <inertial>
      <mass value="0.05"/>
      <inertia
        ixx="0.0042"
        ixy="0.0"
        ixz="0.0"
        iyy="0.0042"
        iyz="0.0"
        izz="0.0001"/>
    </inertial>
    <visual>
      <origin xyz="0.0 0.0 0.0" rpy="0.0 0.0 0.0"/>
      <geometry>
        <cylinder radius="0.015" length="1.0"/>
      </geometry>
      <material name="mat_club_shaft">
        <color rgba="0.2 0.2 0.2 1.0"/>
      </material>
    </visual>
  </link>
  <joint name="club_shaft_to_club_head" type="fixed">
    <parent link="club_shaft"/>
    <child link="club_head"/>
    <origin xyz="0.0 0.0 -0.5" rpy="0.0 0.0 0.0"/>
  </joint>
  <link name="club_head">
    <inertial>
      <mass value="0.2"/>
      <inertia
        ixx="0.0025"
        ixy="0.0"
        ixz="0.0"
        iyy="0.0025"
        iyz="0.0"
        izz="0.0005"/>
    </inertial>
    <visual>
      <origin xyz="0.0 0.0 0.0" rpy="0.0 0.0 0.0"/>
      <geometry>
        <box size="0.12 0.08 0.04"/>
      </geometry>
      <material name="mat_club_head">
        <color rgba="0.15 0.15 0.15 1.0"/>
      </material>
    </visual>
  </link>
  <joint name="hand_left_to_fingers_left" type="revolute">
    <parent link="hand_left"/>
    <child link="fingers_left"/>
    <origin xyz="0.0 0.0 -0.05" rpy="0.0 0.0 0.0"/>
    <axis xyz="0 1 0"/>
    <limit lower="0.0" upper="1.57" effort="1000.0" velocity="10.0"/>
    <dynamics damping="0.5"/>
  </joint>
  <link name="fingers_left">
    <inertial>
      <mass value="0.2"/>
      <inertia
        ixx="0.0003"
        ixy="0.0"
        ixz="0.0"
        iyy="0.0003"
        iyz="0.0"
        izz="0.0001"/>
    </inertial>
    <visual>
      <origin xyz="0.0 0.0 0.0" rpy="0.0 0.0 0.0"/>
      <geometry>
        <box size="0.05 0.08 0.02"/>
      </geometry>
      <material name="mat_fingers_left">
        <color rgba="0.46 0.26 0.1 1.0"/>
      </material>
    </visual>
  </link>
  <joint name="thorax3_to_scapula_right_intermediate" type="revolute">
    <parent link="thorax3"/>
    <child link="scapula_right_intermediate"/>
    <origin xyz="0.0 -0.18 0.28" rpy="0.0 0.0 0.0"/>
    <axis xyz="0 0 1"/>
    <limit lower="-0.35" upper="0.7" effort="1000.0" velocity="10.0"/>
    <dynamics damping="1.0"/>
  </joint>
  <link name="scapula_right_intermediate">
    <inertial>
      <mass value="0.001"/>
      <inertia ixx="0.0001" ixy="0" ixz="0" iyy="0.0001" iyz="0" izz="0.0001"/>
    </inertial>
  </link>
  <joint name="scapula_right_intermediate_to_scapula_right" type="revolute">
    <parent link="scapula_right_intermediate"/>
    <child link="scapula_right"/>
    <origin xyz="0.0 0.0 0.0" rpy="0.0 0.0 0.0"/>
    <axis xyz="0 1 0"/>
    <limit lower="-0.52" upper="0.52" effort="1000.0" velocity="10.0"/>
    <dynamics damping="1.0"/>
  </joint>
  <link name="scapula_right">
    <inertial>
      <mass value="1.5"/>
      <inertia
        ixx="0.008"
        ixy="0.0"
        ixz="0.0"
        iyy="0.008"
        iyz="0.0"
        izz="0.003"/>
    </inertial>
    <visual>
      <origin xyz="0.0 0.0 0.0" rpy="0.0 0.0 0.0"/>
      <geometry>
        <box size="0.12 0.08 0.05"/>
      </geometry>
      <material name="mat_scapula_right">
        <color rgba="0.62 0.42 0.22 1.0"/>
      </material>
    </visual>
  </link>
  <joint name="scapula_right_to_upper_arm_right_gimbal_z" type="revolute">
    <parent link="scapula_right"/>
    <child link="upper_arm_right_gimbal_z"/>
    <origin xyz="0.0 -0.04 0.1" rpy="0.0 0.0 0.0"/>
    <axis xyz="0 1 0"/>
    <limit lower="-1.57" upper="3.1416" effort="1000.0" velocity="10.0"/>
    <dynamics damping="1.5"/>
  </joint>
  <link name="upper_arm_right_gimbal_z">
    <inertial>
      <mass value="0.001"/>
      <inertia ixx="0.0001" ixy="0" ixz="0" iyy="0.0001" iyz="0" izz="0.0001"/>
    </inertial>
  </link>
  <joint name="upper_arm_right_gimbal_z_to_upper_arm_right_gimbal_y" type="revolute">
    <parent link="upper_arm_right_gimbal_z"/>
    <child link="upper_arm_right_gimbal_y"/>
    <origin xyz="0.0 0.0 0.0" rpy="0.0 0.0 0.0"/>
    <axis xyz="1 0 0"/>
    <limit lower="-0.52" upper="2.09" effort="1000.0" velocity="10.0"/>
    <dynamics damping="1.5"/>
  </joint>
  <link name="upper_arm_right_gimbal_y">
    <inertial>
      <mass value="0.001"/>
      <inertia ixx="0.0001" ixy="0" ixz="0" iyy="0.0001" iyz="0" izz="0.0001"/>
    </inertial>
  </link>
  <joint name="upper_arm_right_gimbal_y_to_upper_arm_right" type="revolute">
    <parent link="upper_arm_right_gimbal_y"/>
    <child link="upper_arm_right"/>
    <origin xyz="0.0 0.0 0.0" rpy="0.0 0.0 0.0"/>
    <axis xyz="0 0 1"/>
    <limit lower="-1.57" upper="1.57" effort="1000.0" velocity="10.0"/>
    <dynamics damping="1.5"/>
  </joint>
  <link name="upper_arm_right">
    <inertial>
      <mass value="1.98"/>
      <inertia
        ixx="0.0138"
        ixy="0.0"
        ixz="0.0"
        iyy="0.0138"
        iyz="0.0"
        izz="0.0021"/>
    </inertial>
    <visual>
      <origin xyz="0.0 0.0 0.0" rpy="0.0 0.0 0.0"/>
      <geometry>
        <cylinder radius="0.05" length="0.28"/>
      </geometry>
      <material name="mat_upper_arm_right">
        <color rgba="0.58 0.38 0.18 1.0"/>
      </material>
    </visual>
  </link>
  <joint name="upper_arm_right_to_forearm_right_intermediate" type="revolute">
    <parent link="upper_arm_right"/>
    <child link="forearm_right_intermediate"/>
    <origin xyz="0.0 0.0 -0.26" rpy="0.0 0.0 0.0"/>
    <axis xyz="0 1 0"/>
    <limit lower="0.0" upper="2.62" effort="1000.0" velocity="10.0"/>
    <dynamics damping="3.0"/>
  </joint>
  <link name="forearm_right_intermediate">
    <inertial>
      <mass value="0.001"/>
      <inertia ixx="0.0001" ixy="0" ixz="0" iyy="0.0001" iyz="0" izz="0.0001"/>
    </inertial>
  </link>
  <joint name="forearm_right_intermediate_to_forearm_right" type="revolute">
    <parent link="forearm_right_intermediate"/>
    <child link="forearm_right"/>
    <origin xyz="0.0 0.0 0.0" rpy="0.0 0.0 0.0"/>
    <axis xyz="1 0 0"/>
    <limit lower="-1.57" upper="1.57" effort="1000.0" velocity="10.0"/>
    <dynamics damping="3.0"/>
  </joint>
  <link name="forearm_right">
    <inertial>
      <mass value="1.18"/>
      <inertia
        ixx="0.0074"
        ixy="0.0"
        ixz="0.0"
        iyy="0.0074"
        iyz="0.0"
        izz="0.0009"/>
    </inertial>
    <visual>
      <origin xyz="0.0 0.0 0.0" rpy="0.0 0.0 0.0"/>
      <geometry>
        <cylinder radius="0.045" length="0.26"/>
      </geometry>
      <material name="mat_forearm_right">
        <color rgba="0.54 0.34 0.14 1.0"/>
      </material>
    </visual>
  </link>
  <joint name="forearm_right_to_hand_right_intermediate" type="revolute">
    <parent link="forearm_right"/>
    <child link="hand_right_intermediate"/>
    <origin xyz="0.0 0.0 -0.19" rpy="0.0 0.0 0.0"/>
    <axis xyz="0 1 0"/>
    <limit lower="-1.22" upper="1.22" effort="1000.0" velocity="10.0"/>
    <dynamics damping="1.5"/>
  </joint>
  <link name="hand_right_intermediate">
    <inertial>
      <mass value="0.001"/>
      <inertia ixx="0.0001" ixy="0" ixz="0" iyy="0.0001" iyz="0" izz="0.0001"/>
    </inertial>
  </link>
  <joint name="hand_right_intermediate_to_hand_right" type="revolute">
    <parent link="hand_right_intermediate"/>
    <child link="hand_right"/>
    <origin xyz="0.0 0.0 0.0" rpy="0.0 0.0 0.0"/>
    <axis xyz="0 0 1"/>
    <limit lower="-0.52" upper="0.7" effort="1000.0" velocity="10.0"/>
    <dynamics damping="1.5"/>
  </joint>
  <link name="hand_right">
    <inertial>
      <mass value="0.61"/>
      <inertia
        ixx="0.0011"
        ixy="0.0"
        ixz="0.0"
        iyy="0.0011"
        iyz="0.0"
        izz="0.0004"/>
    </inertial>
    <visual>
      <origin xyz="0.0 0.0 0.0" rpy="0.0 0.0 0.0"/>
      <geometry>
        <cylinder radius="0.04" length="0.19"/>
      </geometry>
      <material name="mat_hand_right">
        <color rgba="0.5 0.3 0.12 1.0"/>
      </material>
    </visual>
  </link>
  <joint name="hand_right_to_fingers_right" type="revolute">
    <parent link="hand_right"/>
    <child link="fingers_right"/>
    <origin xyz="0.0 0.0 -0.05" rpy="0.0 0.0 0.0"/>
    <axis xyz="0 1 0"/>
    <limit lower="0.0" upper="1.57" effort="1000.0" velocity="10.0"/>
    <dynamics damping="0.5"/>
  </joint>
  <link name="fingers_right">
    <inertial>
      <mass value="0.2"/>
      <inertia
        ixx="0.0003"
        ixy="0.0"
        ixz="0.0"
        iyy="0.0003"
        iyz="0.0"
        izz="0.0001"/>
    </inertial>
    <visual>
      <origin xyz="0.0 0.0 0.0" rpy="0.0 0.0 0.0"/>
      <geometry>
        <box size="0.05 0.08 0.02"/>
      </geometry>
      <material name="mat_fingers_right">
        <color rgba="0.46 0.26 0.1 1.0"/>
      </material>
    </visual>
  </link>
  <joint name="pelvis_to_right_thigh_gimbal_z" type="revolute">
    <parent link="pelvis"/>
    <child link="right_thigh_gimbal_z"/>
    <origin xyz="0.0 -0.09 -0.05" rpy="0.0 0.0 0.0"/>
    <axis xyz="0 1 0"/>
    <limit lower="-1.57" upper="1.57" effort="1000.0" velocity="10.0"/>
    <dynamics damping="2.5"/>
  </joint>
  <link name="right_thigh_gimbal_z">
    <inertial>
      <mass value="0.001"/>
      <inertia ixx="0.0001" ixy="0" ixz="0" iyy="0.0001" iyz="0" izz="0.0001"/>
    </inertial>
  </link>
  <joint name="right_thigh_gimbal_z_to_right_thigh_gimbal_y" type="revolute">
    <parent link="right_thigh_gimbal_z"/>
    <child link="right_thigh_gimbal_y"/>
    <origin xyz="0.0 0.0 0.0" rpy="0.0 0.0 0.0"/>
    <axis xyz="1 0 0"/>
    <limit lower="-0.87" upper="0.52" effort="1000.0" velocity="10.0"/>
    <dynamics damping="2.5"/>
  </joint>
  <link name="right_thigh_gimbal_y">
    <inertial>
      <mass value="0.001"/>
      <inertia ixx="0.0001" ixy="0" ixz="0" iyy="0.0001" iyz="0" izz="0.0001"/>
    </inertial>
  </link>
  <joint name="right_thigh_gimbal_y_to_right_thigh" type="revolute">
    <parent link="right_thigh_gimbal_y"/>
    <child link="right_thigh"/>
    <origin xyz="0.0 0.0 0.0" rpy="0.0 0.0 0.0"/>
    <axis xyz="0 0 1"/>
    <limit lower="-0.7" upper="0.7" effort="1000.0" velocity="10.0"/>
    <dynamics damping="2.5"/>
  </joint>
  <link name="right_thigh">
    <inertial>
      <mass value="7.05"/>
      <inertia
        ixx="0.1058"
        ixy="0.0"
        ixz="0.0"
        iyy="0.1058"
        iyz="0.0"
        izz="0.0203"/>
    </inertial>
    <visual>
      <origin xyz="0.0 0.0 0.0" rpy="0.0 0.0 0.0"/>
      <geometry>
        <cylinder radius="0.06" length="0.43"/>
      </geometry>
      <material name="mat_right_thigh">
        <color rgba="0.42 0.32 0.18 1.0"/>
      </material>
    </visual>
  </link>
  <joint name="right_thigh_to_right_shank" type="revolute">
    <parent link="right_thigh"/>
    <child link="right_shank"/>
    <origin xyz="0.0 0.0 -0.43" rpy="0.0 0.0 0.0"/>
    <axis xyz="0 1 0"/>
    <limit lower="0.0" upper="2.62" effort="1000.0" velocity="10.0"/>
    <dynamics damping="5.0"/>
  </joint>
  <link name="right_shank">
    <inertial>
      <mass value="3.53"/>
      <inertia
        ixx="0.0401"
        ixy="0.0"
        ixz="0.0"
        iyy="0.0042"
        iyz="0.0"
        izz="0.0042"/>
    </inertial>
    <visual>
      <origin xyz="0.0 0.0 0.0" rpy="0.0 0.0 0.0"/>
      <geometry>
        <cylinder radius="0.05" length="0.43"/>
      </geometry>
      <material name="mat_right_shank">
        <color rgba="0.38 0.28 0.16 1.0"/>
      </material>
    </visual>
  </link>
  <joint name="right_shank_to_right_foot_intermediate" type="revolute">
    <parent link="right_shank"/>
    <child link="right_foot_intermediate"/>
    <origin xyz="0.0 0.0 -0.43" rpy="0.0 0.0 0.0"/>
    <axis xyz="1 0 0"/>
    <limit lower="-0.7" upper="0.52" effort="1000.0" velocity="10.0"/>
    <dynamics damping="2.0"/>
  </joint>
  <link name="right_foot_intermediate">
    <inertial>
      <mass value="0.001"/>
      <inertia ixx="0.0001" ixy="0" ixz="0" iyy="0.0001" iyz="0" izz="0.0001"/>
    </inertial>
  </link>
  <joint name="right_foot_intermediate_to_right_foot" type="revolute">
    <parent link="right_foot_intermediate"/>
    <child link="right_foot"/>
    <origin xyz="0.0 0.0 0.0" rpy="0.0 0.0 0.0"/>
    <axis xyz="0 1 0"/>
    <limit lower="-0.35" upper="0.35" effort="1000.0" velocity="10.0"/>
    <dynamics damping="2.0"/>
  </joint>
  <link name="right_foot">
    <inertial>
      <mass value="1.37"/>
      <inertia
        ixx="0.0034"
        ixy="0.0"
        ixz="0.0"
        iyy="0.009"
        iyz="0.0"
        izz="0.009"/>
    </inertial>
    <visual>
      <origin xyz="0.0 0.0 0.0" rpy="0.0 0.0 0.0"/>
      <geometry>
        <box size="0.26 0.1 0.07"/>
      </geometry>
      <material name="mat_right_foot">
        <color rgba="0.34 0.24 0.14 1.0"/>
      </material>
    </visual>
  </link>
  <joint name="right_foot_to_right_toes" type="revolute">
    <parent link="right_foot"/>
    <child link="right_toes"/>
    <origin xyz="0.12 0.0 -0.02" rpy="0.0 0.0 0.0"/>
    <axis xyz="0 1 0"/>
    <limit lower="-0.35" upper="0.52" effort="1000.0" velocity="10.0"/>
    <dynamics damping="0.5"/>
  </joint>
  <link name="right_toes">
    <inertial>
      <mass value="0.3"/>
      <inertia
        ixx="0.0005"
        ixy="0.0"
        ixz="0.0"
        iyy="0.0005"
        iyz="0.0"
        izz="0.0002"/>
    </inertial>
    <visual>
      <origin xyz="0.0 0.0 0.0" rpy="0.0 0.0 0.0"/>
      <geometry>
        <box size="0.1 0.08 0.03"/>
      </geometry>
      <material name="mat_right_toes">
        <color rgba="0.32 0.22 0.12 1.0"/>
      </material>
    </visual>
  </link>
</robot>